Workbook

Sheet Calculator
A1: Sunstone Pricing Calculator
A3: Customer Inputs
A4: Customer Name: | B4: Zambia Sugar
A5: Quote Date: | B5: =TODAY() -> 46203
A6: Number of Vehicles: | B6: 20
A8: Product Selection & Pricing
A9: Product | B9: Include? | C9: List Price (R/veh/mo) | D9: Effective Price (R/veh/mo) | E9: Monthly Cost(R) | F9: Annual Cost(R)
A10: Tracking | B10: TRUE | C10: =Config!D5 -> 276.66667 | D10: =C10*$B$19*$B$21 -> 235.16667 | E10: =B10*D10*$B$6 -> 4703.3333 | F10: =E10*12 -> 56440
A11: Fuel plus tracking | B11: TRUE | C11: =Config!D6 -> 332 | D11: =C11*$B$19*$B$21 -> 282.2 | E11: =B11*D11*$B$6 -> 5644 | F11: =E11*12 -> 67728
A12: Route Builder | B12: TRUE | C12: =Config!D7 -> 200 | D12: =C12*$B$19*$B$21 -> 170 | E12: =B12*D12*$B$6 -> 3400 | F12: =E12*12 -> 40800
A13: Digital Journey | B13: TRUE | C13: =Config!D8 -> 332 | D13: =C13*$B$19*$B$21 -> 282.2 | E13: =B13*D13*$B$6 -> 5644 | F13: =E13*12 -> 67728
A14: Stock Master | B14: FALSE | C14: =Config!D9 -> 1000 | D14: =C14*$B$19*$B$21 -> 850 | E14: =B14*D14*$B$6 -> 0 | F14: =E14*12 -> 0
A15: Configuration Check: | B15: =IF(AND(B10,B11),"INVALID: Fuel already includes Tracking. Please deselect one.","Configuration is valid.") -> INVALID: Fuel already includes Tracking. Please deselect one.
A17: Discount Summary
A18: Products in Bundle: | B18: =SUMPRODUCT(--B10:B14) -> 4
A19: Bundle Multiplier: | B19: =IFERROR(VLOOKUP(B18,Config!$A$14:$C$18,3,FALSE),1) -> 0.85 | C19: =IFERROR(VLOOKUP(B18,Config!$A$14:$C$18,2,FALSE),0) -> 0.15 | D19: bundle discount
A20: Volume Tier: | B20: =VLOOKUP($B$6,Config!$A$22:$E$26,3,TRUE) -> SMB
A21: Volume Multiplier: | B21: =VLOOKUP($B$6,Config!$A$22:$E$26,5,TRUE) -> 1 | C21: =VLOOKUP($B$6,Config!$A$22:$E$26,4,TRUE) -> 0 | D21: volume discount
A23: TOTAL MONTHLY REVENUE: | E23: =SUM(E10:E14) -> 19391.333 | F23: =SUM(F10:F14) -> 232696
A24: EFFECTIVE BLENDED DISCOUNT: | E24: =1-B19*B21 -> 0.15
A26: BLENDED PRICE PER VEHICLE / MONTH
A27: =IFERROR(E23/B6,0) -> 969.56667
A30: After bundle and volume discounts, blended across all selected products
A32: ⚠ Implementation fee is quoted separately based on project scope, integrations, and training requirements.
A34: How to use:
A35: 1. Enter customer name and number of vehicles in the YELLOW cells.
A36: 2. For each product, click the YELLOW "Include?" cell and pick 1 (☑ = include) or 0 (☐ = exclude).
A37: TIP: In Excel 365 you can select cells B10:B14 and use Insert > Checkbox to upgrade these to
A38: true clickable checkboxes — the formulas already use numeric truthy values so nothing else changes.
A39: IMPORTANT: Tracking and Fuel are mutually exclusive (Fuel already includes Tracking).
A40: The Configuration Check row will turn RED if both are selected.
A41: 3. The Effective Price, Monthly Revenue, and Annual Revenue update automatically.
A42: 4. The gold panel at row 27 shows the blended price per vehicle/month (the customer-facing headline number).
A43: 5. Check the "Internal Margin" sheet for margin %, contribution, and step-cost warnings.
A44: 6. Switch to "Customer Quote" sheet for the client-facing version (no cost/margin data).

Sheet Hardware
A1: Hardware Costing
A2: One-time hardware + installation charges. Installation auto-computes from Hardware selections.
A4: Fleet Composition
A5: Total vehicles (from Calculator): | B5: 20 | C5: ← linked from Calculator!B6
A6: Fuel-monitored — single-tank: | B6: 0 | C6: ← YELLOW. Single-tank vehicles getting a Fuel Probe Kit (GPS + 1 probe).
A7: Fuel-monitored — dual-tank: | B7: 0 | C7: ← YELLOW. Dual-tank vehicles getting a Fuel Probe Kit (GPS + 2 probes). (Tracking-only vehicles = Total − these two.)
A8: =IF(SUMPRODUCT(--(C14:C20<>0),--(D14:D20=0))>0,"⚠ A ticked hardware item has ZERO quantity. Fuel Probe Kit qty comes from Fleet Composition above (single-tank B6 / dual-tank B7); Trailer GPS qty is entered in its own row. Set the count so it flows through.","") -> ⚠ A ticked hardware item has ZERO quantity. Fuel Probe Kit qty comes from Fleet Composition above (single-tank B6 / dual-tank B7); Trailer GPS qty is entered in its own row. Set the count so it flows through.
A9: International Shipping & Customs
A10: Outside South Africa? (adds 20% surcharge to hardware items): | F10: FALSE | G10: (rate from Config!B50)
A12: Hardware Items
A13: SKU | B13: Pairs with | C13: Include? | D13: Qty | E13: Sell Price (R) | F13: Subtotal (R) | G13: Notes
A14: Blackview Fort 1 | B14: Digital Journey | C14: FALSE | D14: =$B$5 -> 20 | E14: =VLOOKUP(A14,Config!$A$35:$D$37,4,FALSE) -> 4922.5 | F14: =C14*D14*E14 -> 0 | G14: Choose model for DJ drivers via dropdown
A15: Oukitel G1S | B15: Stock Master | C15: 0 | D15: =$B$5 -> 20 | E15: =VLOOKUP(A15,Config!$A$35:$D$37,4,FALSE) -> 3716.25 | F15: =C15*D15*E15 -> 0 | G15: Independent model for Stock Master users (often different qty)
A16: Urovo Printer K419 (incl. case + car charger) | B16: Digital Journey | C16: FALSE | D16: =$B$5 -> 20 | E16: =Config!$D$38 -> 4507.5 | F16: =C16*D16*E16 -> 0 | G16: Default 1 per vehicle; rep can override
A17: Teltonika FMB125 | B17: Tracking-only | C17: FALSE | D17: =MAX($B$5-$B$6-$B$7,0) -> 20 | E17: =Config!$D$39 -> 798.75 | F17: =C17*D17*E17 -> 0 | G17: Tracking-only vehicles (auto = Total − fuel vehicles). Fuel vehicles get the Kit below.
A18: Queclink GV620MG | B18: Tracking (trailers) | C18: FALSE | D18: 0 | E18: =Config!$D$40 -> 1753.75 | F18: =C18*D18*E18 -> 0 | G18: Enter # of trailers in Qty column (YELLOW)
A19: Fuel Probe Kit — Single-Tank (GPS + 1 probe) | B19: Fuel | C19: FALSE | D19: =$B$6 -> 0 | E19: =Config!$D$39+Config!$D$41 -> 2985 | F19: =C19*D19*E19 -> 0 | G19: Incl. Teltonika GPS + 1 Omnicomm probe. Qty = single-tank fuel count (set in Fleet Composition, B6).
A20: Fuel Probe Kit — Dual-Tank (GPS + 2 probes) | B20: Fuel | C20: FALSE | D20: =$B$7 -> 0 | E20: =Config!$D$39+2*Config!$D$41 -> 5171.25 | F20: =C20*D20*E20 -> 0 | G20: Incl. Teltonika GPS + 2 Omnicomm probes. Qty = dual-tank fuel count (set in Fleet Composition, B7).
A22: Hardware subtotal: | F22: =SUM(F14:F20) -> 0
A23: International shipping & customs surcharge: | F23: =IF($F$10,F22*Config!$B$53,0) -> 0
A24: Hardware total (incl. shipping if any): | F24: =F22+F23 -> 0
A26: Installation Charges (auto-computed from Hardware selections + Fleet Composition)
A27: Scenario | D27: Qty | E27: Rate (R) | F27: Subtotal (R) | G27: Notes
A28: GPS Tracking installation | D28: =IF($C$17,$D$17,0) -> 0 | E28: =Config!$B$46 -> 800 | F28: =D28*E28 -> 0 | G28: Tracking-only vehicles (R800 each)
A29: Fuel Probe Kit installation — single-tank | D29: =IF($C$19,$D$19,0) -> 0 | E29: =Config!$B$48 -> 1600 | F29: =D29*E29 -> 0 | G29: GPS + 1 probe, one combined visit
A30: Fuel Probe Kit installation — dual-tank | D30: =IF($C$20,$D$20,0) -> 0 | E30: =Config!$B$49 -> 2200 | F30: =D30*E30 -> 0 | G30: GPS + 2 probes, one combined visit
A31: Trailer GPS installation | D31: =IF($C$18,$D$18,0) -> 0 | E31: =Config!$B$46 -> 800 | F31: =D31*E31 -> 0 | G31: R800 per trailer
A33: Installation subtotal: | F33: =SUM(F28:F31) -> 0
A35: GRAND TOTAL — Hardware + Installation: | F35: =F24+F33 -> 0
A37: TOTAL HARDWARE + INSTALLATION COST
A38: =F35 -> 0
A41: Sum of selected hardware items (including any international shipping) + auto-computed installation charges
A43: How to use this sheet:
A44: 1. Fleet Composition: enter single-tank fuel vehicles (B6) and dual-tank fuel vehicles (B7).
A45: Tracking-only vehicles = Total − these two, and auto-fill the Vehicle GPS quantity.
A46: 2. Tick "Outside South Africa?" (F10) for international shipping (20% on hardware items only).
A47: 3. Pick the handset model for Digital Journey (A14) and Stock Master (A15) from their dropdowns — independent choices.
A48: 4. Tick Include? on each hardware item. Fuel vehicles use the Fuel Probe Kit (GPS + probe(s) bundled);
A49: tracking-only vehicles use the standalone Vehicle GPS. Each Kit carries its combined install rate.
A50: 5. Installation (rows 28-31) follows each ticked item automatically — Kit single = R1,600, Kit dual = R2,200.
...

Sheet Rental
A1: Rental Pricing — All-Inclusive Monthly
A2: Bakes SaaS subscription + hardware + installation into one monthly fee. Configure the deal on Calculator + Hardware first.
A4: Rental Configuration
A5: Rental term (months): | B5: 36 | C5: ← choose 12, 24 or 36 (shorter term = higher monthly)
A6: Rental mode: | B6: Pure Rental | C6: ← Pure Rental (you retain ownership) or Rent-to-Own (customer owns at end)
A7: Rental annual rate (from Config): | B7: =Config!$B$58 -> 0.18 | C7: FINANCING only = cost of capital (Config!B53) + financing margin (Config!B54). Hardware markup is already in the sell price.
A8: Monthly factor per R1 of capital (auto): | B8: =-PMT(B7/12,B5,1) -> 0.036152396 | C8: PMT annuity factor for the chosen rate & term
A10: Deal (linked from Calculator + Hardware)
A11: Vehicles: | B11: 140
A12: Monthly SaaS subscription (total): | B12: =Calculator!E23 -> 19391.333
A13: Hardware total (incl. shipping): | B13: =Hardware!F24 -> 0
A14: Installation total: | B14: =Hardware!F33 -> 0
A15: Capital to finance (hardware + install): | B15: =Hardware!F35 -> 0
A17: Rental Bundle — First Term
A18: Monthly SaaS (recurring software): | B18: =B12 -> 19391.333
A19: Monthly hardware + install rental (amortised): | B19: =-PMT(B7/12,B5,B15) -> 0 | C19: PMT(rate÷12, term, capital) — recovers hardware+install + financing over the term
A20: TOTAL monthly rental bundle: | B20: =B18+B19 -> 19391.333
A21: Per vehicle / month: | B21: =IFERROR(B20/B11,0) -> 138.50952
A22: Total payable over the full term: | B22: =B20*B5 -> 698088
A23: Purchase-model comparison (upfront + monthly SaaS): | B23: =Hardware!F35+Implementation!F23 -> 139125 | C23: one-time (hardware+install+implementation) the customer avoids by renting
A25: End-of-Term Renewal Options
A26: Refresh — new hardware, fresh term (per vehicle/mo): | B26: =B21 -> 138.50952 | C26: same full rate; resets the hardware-recovery cycle with current kit
A27: Retain existing hardware (per vehicle/mo): | B27: =IFERROR(B12/B11,0)+IF(B6="Pure Rental",IFERROR(B13*Config!$B$59/B11,0),0) -> 138.50952 | C27: hardware already paid off → software + light support only (your highest-margin revenue)
A28: Saving vs first term (retain route): | B28: =IFERROR(1-B27/B21,0) -> 0
A30: =IF(B6="Pure Rental","MODE: Pure Rental — Sunstone retains ownership; monthly fee is typically a fully-deductible operating expense for the customer (confirm with their tax advisor). Hardware is not contractually transferred (preserves operating-lease treatment).","MODE: Rent-to-Own — customer owns the hardware at end of term; treated like a financed purchase for tax (customer capitalises & depreciates). Renewal = software only on owned kit.") -> MODE: Pure Rental — Sunstone retains ownership; monthly fee is typically a fully-deductible operating expense for the customer (confirm with their tax advisor). Hardware is not contractually transferred (preserves operating-lease treatment).
A33: RENTAL BUNDLE — PER VEHICLE / MONTH (ALL-INCLUSIVE)
A34: =B21 -> 138.50952
A37: =B5&"-month term • "&B6&" • zero upfront — software, hardware & installation in one monthly fee" -> 36-month term • Pure Rental • zero upfront — software, hardware & installation in one monthly fee
A39: How to use this sheet:
A40: 1. Configure the deal first on Calculator (products + vehicles) and Hardware (devices + fleet composition).
A41: 2. Choose the rental term (B5: 12/24/36) and mode (B6: Pure Rental / Rent-to-Own).
A42: 3. The monthly bundle = SaaS + amortised hardware & install (PMT at the Config rental rate over the term).
A43: 4. The gold panel shows the all-inclusive per-vehicle/month price — your headline rental number.
A44: 5. The renewal block shows the lifecycle: refresh (new term) vs retain existing kit (software + light support).
A45: 6. Tune the rental rate (Config!B53) and renewal support fee (Config!B54) to your financing cost & margin.

Sheet Implementation
A1: Once-Off Implementation Costing
A2: Time-and-materials build-up. Hours, resource tier (Consultant/Senior), and per-line discounts are editable per project.
A4: Customer: | B4: =Calculator!B4 -> Zambia Sugar
A5: Vehicles: | B5: =Calculator!B6 -> 20
A6: Date: | B6: =Calculator!B5 -> 46203
A8: Implementation Activities (Estimated Once-Off)
A9: Description | B9: Hours | C9: Senior? | D9: Rate (R/hr) | E9: Discount % | F9: Total (R) | G9: Notes
A10: Project Management | B10: 30 | C10: TRUE | D10: =IF(C10,Config!$B$31,Config!$B$30) -> 1325 | E10: 0 | F10: =B10*D10*(1-E10) -> 39750
A11: Design and Integration | B11: 15 | C11: TRUE | D11: =IF(C11,Config!$B$31,Config!$B$30) -> 1325 | E11: 0 | F11: =B11*D11*(1-E11) -> 19875
A12: MasterData and Database setup | B12: 10 | C12: TRUE | D12: =IF(C12,Config!$B$31,Config!$B$30) -> 1325 | E12: 0 | F12: =B12*D12*(1-E12) -> 13250
A13: Reporting setup | B13: 5 | C13: TRUE | D13: =IF(C13,Config!$B$31,Config!$B$30) -> 1325 | E13: 0 | F13: =B13*D13*(1-E13) -> 6625
A14: Testing | B14: 10 | C14: TRUE | D14: =IF(C14,Config!$B$31,Config!$B$30) -> 1325 | E14: 0 | F14: =B14*D14*(1-E14) -> 13250
A15: User Acceptance Testing | B15: 5 | C15: TRUE | D15: =IF(C15,Config!$B$31,Config!$B$30) -> 1325 | E15: 0 | F15: =B15*D15*(1-E15) -> 6625
A16: Training — Tracking | B16: 5 | C16: TRUE | D16: =IF(C16,Config!$B$31,Config!$B$30) -> 1325 | E16: 0 | F16: =IF(Calculator!B10,B16*D16*(1-E16),0) -> 6625 | G16: =IF(Calculator!B10,"Billed (product selected)","Not billed (product not selected)") -> Billed (product selected)
A17: Training — Fuel | B17: 5 | C17: TRUE | D17: =IF(C17,Config!$B$31,Config!$B$30) -> 1325 | E17: 0 | F17: =IF(Calculator!B11,B17*D17*(1-E17),0) -> 6625 | G17: =IF(Calculator!B11,"Billed (product selected)","Not billed (product not selected)") -> Billed (product selected)
A18: Training — Route Builder | B18: 10 | C18: TRUE | D18: =IF(C18,Config!$B$31,Config!$B$30) -> 1325 | E18: 0 | F18: =IF(Calculator!B12,B18*D18*(1-E18),0) -> 13250 | G18: =IF(Calculator!B12,"Billed (product selected)","Not billed (product not selected)") -> Billed (product selected)
A19: Training — Digital Journey | B19: 10 | C19: TRUE | D19: =IF(C19,Config!$B$31,Config!$B$30) -> 1325 | E19: 0 | F19: =IF(Calculator!B13,B19*D19*(1-E19),0) -> 13250 | G19: =IF(Calculator!B13,"Billed (product selected)","Not billed (product not selected)") -> Billed (product selected)
A20: Training — Stock Master | B20: 10 | C20: 0 | D20: =IF(C20,Config!$B$31,Config!$B$30) -> 1000 | E20: 0 | F20: =IF(Calculator!B14,B20*D20*(1-E20),0) -> 0 | G20: =IF(Calculator!B14,"Billed (product selected)","Not billed (product not selected)") -> Not billed (product not selected)
A21: Go Live and Hypercare | B21: 40 | C21: TRUE | D21: =IF(C21,Config!$B$31,Config!$B$30) -> 1325 | E21: 1 | F21: =B21*D21*(1-E21) -> 0 | G21: Default 100% discount (value-add)
A23: TOTAL ONE-TIME IMPLEMENTATION: | F23: =SUM(F10:F21) -> 139125
A24: Total billable hours (effective): | F24: =B10*(1-E10)+B11*(1-E11)+B12*(1-E12)+B13*(1-E13)+B14*(1-E14)+B15*(1-E15)+IF(Calculator!B10,B16*(1-E16),0)+IF(Calculator!B11,B17*(1-E17),0)+IF(Calculator!B12,B18*(1-E18),0)+IF(Calculator!B13,B19*(1-E19),0)+IF(Calculator!B14,B20*(1-E20),0)+B21*(1-E21) -> 105
A25: Senior hours / Consultant hours: | F25: =(IF(C10,B10*(1-E10),0)+IF(C11,B11*(1-E11),0)+IF(C12,B12*(1-E12),0)+IF(C13,B13*(1-E13),0)+IF(C14,B14*(1-E14),0)+IF(C15,B15*(1-E15),0)+IF(AND(Calculator!B10,C16),B16*(1-E16),0)+IF(AND(Calculator!B11,C17),B17*(1-E17),0)+IF(AND(Calculator!B12,C18),B18*(1-E18),0)+IF(AND(Calculator!B13,C19),B19*(1-E19),0)+IF(AND(Calculator!B14,C20),B20*(1-E20),0)+IF(C21,B21*(1-E21),0))&" Senior / "&(IF(C10,0,B10*(1-E10))+IF(C11,0,B11*(1-E11))+IF(C12,0,B12*(1-E12))+IF(C13,0,B13*(1-E13))+IF(C14,0,B14*(1-E14))+IF(C15,0,B15*(1-E15))+IF(AND(Calculator!B10,NOT(C16)),B16*(1-E16),0)+IF(AND(Calculator!B11,NOT(C17)),B17*(1-E17),0)+IF(AND(Calculator!B12,NOT(C18)),B18*(1-E18),0)+IF(AND(Calculator!B13,NOT(C19)),B19*(1-E19),0)+IF(AND(Calculator!B14,NOT(C20)),B20*(1-E20),0)+IF(C21,0,B21*(1-E21)))&" Consultant" -> 105 Senior / 0 Consultant
A27: TOTAL ONE-TIME IMPLEMENTATION COST
A28: =F23 -> 139125
A31: Sum of all itemised activities above (training rows included only where the product is selected on Calculator)
A33: How to use this sheet:
A34: 1. YELLOW cells are editable per project: Hours (B), Senior? checkbox (C), Discount % (E), and Notes (G).
A35: 2. The Rate column (D) auto-flips: ☑ Senior? = Senior Consultant rate (Config!B30); ☐ = Consultant rate (Config!B29).
A36: 3. Training rows only contribute to the total when the matching product is selected on the Calculator.
A37: 4. Go Live and Hypercare defaults to 100% discount (free); change E21 to charge it.
A38: 5. The Customer Quote shows only non-zero lines (no Senior/Consultant column — customer sees the effective rate per line).

Sheet Customer Quote
A1: SUNSTONE LOGISTIC SYSTEMS
A2: Solution Quotation — Subscription, Implementation & Hardware
A4: Prepared for: | B4: =Calculator!B4 -> Zambia Sugar
A5: Quote date: | B5: =Calculator!B5 -> 46203
A6: Fleet size: | B6: =Calculator!B6&" vehicles" -> 20 vehicles
A8: Subscription Items
A9: Product | B9: Vehicles | C9: Price per Vehicle/mo | D9: Monthly (R) | E9: Annual (R)
A10: =IF(Calculator!B10,"Tracking","") -> Tracking | B10: =IF(Calculator!B10,Calculator!$B$6,"") -> 20 | C10: =IF(Calculator!B10,Calculator!D10,"") -> 235.16667 | D10: =IF(Calculator!B10,Calculator!E10,"") -> 4703.3333 | E10: =IF(Calculator!B10,Calculator!F10,"") -> 56440
A11: =IF(Calculator!B11,"Fuel","") -> Fuel | B11: =IF(Calculator!B11,Calculator!$B$6,"") -> 20 | C11: =IF(Calculator!B11,Calculator!D11,"") -> 282.2 | D11: =IF(Calculator!B11,Calculator!E11,"") -> 5644 | E11: =IF(Calculator!B11,Calculator!F11,"") -> 67728
A12: =IF(Calculator!B12,"Route Builder","") -> Route Builder | B12: =IF(Calculator!B12,Calculator!$B$6,"") -> 20 | C12: =IF(Calculator!B12,Calculator!D12,"") -> 170 | D12: =IF(Calculator!B12,Calculator!E12,"") -> 3400 | E12: =IF(Calculator!B12,Calculator!F12,"") -> 40800
A13: =IF(Calculator!B13,"Digital Journey","") -> Digital Journey | B13: =IF(Calculator!B13,Calculator!$B$6,"") -> 20 | C13: =IF(Calculator!B13,Calculator!D13,"") -> 282.2 | D13: =IF(Calculator!B13,Calculator!E13,"") -> 5644 | E13: =IF(Calculator!B13,Calculator!F13,"") -> 67728
A14: =IF(Calculator!B14,"Stock Master","") | B14: =IF(Calculator!B14,Calculator!$B$6,"") | C14: =IF(Calculator!B14,Calculator!D14,"") | D14: =IF(Calculator!B14,Calculator!E14,"") | E14: =IF(Calculator!B14,Calculator!F14,"")
A16: Total subscription value (excl. VAT) | D16: =Calculator!E23 -> 19391.333 | E16: =Calculator!F23 -> 232696
A23: One-Time Implementation (Setup, Config & Project Services)
A24: Description | B24: Hours | C24: Rate (R/hr) | D24: Discount | E24: Total (R)
A25: =IF(Implementation!F10>0,Implementation!A10,"") -> Project Management | B25: =IF(Implementation!F10>0,Implementation!B10,"") -> 30 | C25: =IF(Implementation!F10>0,Implementation!D10,"") -> 1325 | D25: =IF(AND(Implementation!F10>0,Implementation!E10>0),Implementation!E10,"") | E25: =IF(Implementation!F10>0,Implementation!F10,"") -> 39750
A26: =IF(Implementation!F11>0,Implementation!A11,"") -> Design and Integration | B26: =IF(Implementation!F11>0,Implementation!B11,"") -> 15 | C26: =IF(Implementation!F11>0,Implementation!D11,"") -> 1325 | D26: =IF(AND(Implementation!F11>0,Implementation!E11>0),Implementation!E11,"") | E26: =IF(Implementation!F11>0,Implementation!F11,"") -> 19875
A27: =IF(Implementation!F12>0,Implementation!A12,"") -> MasterData and Database setup | B27: =IF(Implementation!F12>0,Implementation!B12,"") -> 10 | C27: =IF(Implementation!F12>0,Implementation!D12,"") -> 1325 | D27: =IF(AND(Implementation!F12>0,Implementation!E12>0),Implementation!E12,"") | E27: =IF(Implementation!F12>0,Implementation!F12,"") -> 13250
A28: =IF(Implementation!F13>0,Implementation!A13,"") -> Reporting setup | B28: =IF(Implementation!F13>0,Implementation!B13,"") -> 5 | C28: =IF(Implementation!F13>0,Implementation!D13,"") -> 1325 | D28: =IF(AND(Implementation!F13>0,Implementation!E13>0),Implementation!E13,"") | E28: =IF(Implementation!F13>0,Implementation!F13,"") -> 6625
A29: =IF(Implementation!F14>0,Implementation!A14,"") -> Testing | B29: =IF(Implementation!F14>0,Implementation!B14,"") -> 10 | C29: =IF(Implementation!F14>0,Implementation!D14,"") -> 1325 | D29: =IF(AND(Implementation!F14>0,Implementation!E14>0),Implementation!E14,"") | E29: =IF(Implementation!F14>0,Implementation!F14,"") -> 13250
A30: =IF(Implementation!F15>0,Implementation!A15,"") -> User Acceptance Testing | B30: =IF(Implementation!F15>0,Implementation!B15,"") -> 5 | C30: =IF(Implementation!F15>0,Implementation!D15,"") -> 1325 | D30: =IF(AND(Implementation!F15>0,Implementation!E15>0),Implementation!E15,"") | E30: =IF(Implementation!F15>0,Implementation!F15,"") -> 6625
A31: =IF(Implementation!F16>0,Implementation!A16,"") -> Training — Tracking | B31: =IF(Implementation!F16>0,Implementation!B16,"") -> 5 | C31: =IF(Implementation!F16>0,Implementation!D16,"") -> 1325 | D31: =IF(AND(Implementation!F16>0,Implementation!E16>0),Implementation!E16,"") | E31: =IF(Implementation!F16>0,Implementation!F16,"") -> 6625
A32: =IF(Implementation!F17>0,Implementation!A17,"") -> Training — Fuel | B32: =IF(Implementation!F17>0,Implementation!B17,"") -> 5 | C32: =IF(Implementation!F17>0,Implementation!D17,"") -> 1325 | D32: =IF(AND(Implementation!F17>0,Implementation!E17>0),Implementation!E17,"") | E32: =IF(Implementation!F17>0,Implementation!F17,"") -> 6625
A33: =IF(Implementation!F18>0,Implementation!A18,"") -> Training — Route Builder | B33: =IF(Implementation!F18>0,Implementation!B18,"") -> 10 | C33: =IF(Implementation!F18>0,Implementation!D18,"") -> 1325 | D33: =IF(AND(Implementation!F18>0,Implementation!E18>0),Implementation!E18,"") | E33: =IF(Implementation!F18>0,Implementation!F18,"") -> 13250
A34: =IF(Implementation!F19>0,Implementation!A19,"") -> Training — Digital Journey | B34: =IF(Implementation!F19>0,Implementation!B19,"") -> 10 | C34: =IF(Implementation!F19>0,Implementation!D19,"") -> 1325 | D34: =IF(AND(Implementation!F19>0,Implementation!E19>0),Implementation!E19,"") | E34: =IF(Implementation!F19>0,Implementation!F19,"") -> 13250
A35: =IF(Implementation!F20>0,Implementation!A20,"") | B35: =IF(Implementation!F20>0,Implementation!B20,"") | C35: =IF(Implementation!F20>0,Implementation!D20,"") | D35: =IF(AND(Implementation!F20>0,Implementation!E20>0),Implementation!E20,"") | E35: =IF(Implementation!F20>0,Implementation!F20,"")
A36: =IF(Implementation!F21>0,Implementation!A21,"") | B36: =IF(Implementation!F21>0,Implementation!B21,"") | C36: =IF(Implementation!F21>0,Implementation!D21,"") | D36: =IF(AND(Implementation!F21>0,Implementation!E21>0),Implementation!E21,"") | E36: =IF(Implementation!F21>0,Implementation!F21,"")
A37: Total one-time implementation (excl. VAT) | E37: =Implementation!F23 -> 139125
A39: One-Time Hardware & Installation
A40: Description | B40: Qty | C40: Unit Price (R) | E40: Total (R)
A41: =IF(Hardware!F14>0,"Digital Journey Handset ("&Hardware!A14&")","") | B41: =IF(Hardware!F14>0,Hardware!D14,"") | C41: =IF(Hardware!F14>0,Hardware!E14,"") | E41: =IF(Hardware!F14>0,Hardware!F14,"")
A42: =IF(Hardware!F15>0,"Stock Master Handset ("&Hardware!A15&")","") | B42: =IF(Hardware!F15>0,Hardware!D15,"") | C42: =IF(Hardware!F15>0,Hardware!E15,"") | E42: =IF(Hardware!F15>0,Hardware!F15,"")
A43: =IF(Hardware!F16>0,Hardware!A16,"") | B43: =IF(Hardware!F16>0,Hardware!D16,"") | C43: =IF(Hardware!F16>0,Hardware!E16,"") | E43: =IF(Hardware!F16>0,Hardware!F16,"")
A44: =IF(Hardware!F17>0,"Vehicle GPS Tracker ("&Hardware!A17&")","") | B44: =IF(Hardware!F17>0,Hardware!D17,"") | C44: =IF(Hardware!F17>0,Hardware!E17,"") | E44: =IF(Hardware!F17>0,Hardware!F17,"")
A45: =IF(Hardware!F18>0,"Trailer GPS Tracker ("&Hardware!A18&")","") | B45: =IF(Hardware!F18>0,Hardware!D18,"") | C45: =IF(Hardware!F18>0,Hardware!E18,"") | E45: =IF(Hardware!F18>0,Hardware!F18,"")
A46: =IF(Hardware!F19>0,Hardware!A19,"") | B46: =IF(Hardware!F19>0,Hardware!D19,"") | C46: =IF(Hardware!F19>0,Hardware!E19,"") | E46: =IF(Hardware!F19>0,Hardware!F19,"")
A47: =IF(Hardware!F20>0,Hardware!A20,"") | B47: =IF(Hardware!F20>0,Hardware!D20,"") | C47: =IF(Hardware!F20>0,Hardware!E20,"") | E47: =IF(Hardware!F20>0,Hardware!F20,"")
A48: =IF(Hardware!F23>0,"International shipping & customs (20%)","") | E48: =IF(Hardware!F23>0,Hardware!F23,"")
A49: =IF(Hardware!F28>0,Hardware!A28,"") | B49: =IF(Hardware!F28>0,Hardware!D28,"") | C49: =IF(Hardware!F28>0,Hardware!E28,"") | E49: =IF(Hardware!F28>0,Hardware!F28,"")
A50: =IF(Hardware!F29>0,Hardware!A29,"") | B50: =IF(Hardware!F29>0,Hardware!D29,"") | C50: =IF(Hardware!F29>0,Hardware!E29,"") | E50: =IF(Hardware!F29>0,Hardware!F29,"")
...

Sheet Internal Margin
A1: Internal Margin Analysis — NOT FOR CLIENT
A2: Customer: | B2: =Calculator!B4 -> Zambia Sugar | E2: Vehicles: | F2: =Calculator!B6 -> 20
A4: Per-Product Margin Breakdown
A5: Product | B5: Selected | C5: Monthly Revenue (R) | D5: Marginal Cost (R/lic/mo) | E5: Monthly Cost (R) | F5: Contribution (R) | G5: Gross Margin % | H5: Step-Cost Warning
A6: Tracking | B6: =IF(Calculator!B10,"☑","☐") -> ☑ | C6: =Calculator!E10 -> 4703.3333 | D6: =Config!B5 -> 83 | E6: =Calculator!B10*D6*$F$2 -> 1660 | F6: =C6-E6 -> 3043.3333 | G6: =IFERROR(F6/C6,0) -> 0.64705882 | H6: =IF(AND(Calculator!B10,$F$2>=Config!E5),"⚠ "&ROUNDDOWN($F$2/Config!E5,0)&" step(s) crossed: +R"&TEXT(ROUNDDOWN($F$2/Config!E5,0)*Config!F5,"#,##0")&"/mo cost",IF(Calculator!B10,"ok","—")) -> ok
A7: Fuel | B7: =IF(Calculator!B11,"☑","☐") -> ☑ | C7: =Calculator!E11 -> 5644 | D7: =Config!B6 -> 83 | E7: =Calculator!B11*D7*$F$2 -> 1660 | F7: =C7-E7 -> 3984 | G7: =IFERROR(F7/C7,0) -> 0.70588235 | H7: =IF(AND(Calculator!B11,$F$2>=Config!E6),"⚠ "&ROUNDDOWN($F$2/Config!E6,0)&" step(s) crossed: +R"&TEXT(ROUNDDOWN($F$2/Config!E6,0)*Config!F6,"#,##0")&"/mo cost",IF(Calculator!B11,"ok","—")) -> ok
A8: Route Builder | B8: =IF(Calculator!B12,"☑","☐") -> ☑ | C8: =Calculator!E12 -> 3400 | D8: =Config!B7 -> 50 | E8: =Calculator!B12*D8*$F$2 -> 1000 | F8: =C8-E8 -> 2400 | G8: =IFERROR(F8/C8,0) -> 0.70588235 | H8: =IF(AND(Calculator!B12,$F$2>=Config!E7),"⚠ "&ROUNDDOWN($F$2/Config!E7,0)&" step(s) crossed: +R"&TEXT(ROUNDDOWN($F$2/Config!E7,0)*Config!F7,"#,##0")&"/mo cost",IF(Calculator!B12,"ok","—")) -> ok
A9: Digital Journey | B9: =IF(Calculator!B13,"☑","☐") -> ☑ | C9: =Calculator!E13 -> 5644 | D9: =Config!B8 -> 83 | E9: =Calculator!B13*D9*$F$2 -> 1660 | F9: =C9-E9 -> 3984 | G9: =IFERROR(F9/C9,0) -> 0.70588235 | H9: =IF(AND(Calculator!B13,$F$2>=Config!E8),"⚠ "&ROUNDDOWN($F$2/Config!E8,0)&" step(s) crossed: +R"&TEXT(ROUNDDOWN($F$2/Config!E8,0)*Config!F8,"#,##0")&"/mo cost",IF(Calculator!B13,"ok","—")) -> ok
A10: Stock Master | B10: =IF(Calculator!B14,"☑","☐") -> ☐ | C10: =Calculator!E14 -> 0 | D10: =Config!B9 -> 250 | E10: =Calculator!B14*D10*$F$2 -> 0 | F10: =C10-E10 -> 0 | G10: =IFERROR(F10/C10,0) -> 0 | H10: =IF(AND(Calculator!B14,$F$2>=Config!E9),"⚠ "&ROUNDDOWN($F$2/Config!E9,0)&" step(s) crossed: +R"&TEXT(ROUNDDOWN($F$2/Config!E9,0)*Config!F9,"#,##0")&"/mo cost",IF(Calculator!B14,"ok","—")) -> —
A11: TOTAL | C11: =SUM(C6:C10) -> 19391.333 | E11: =SUM(E6:E10) -> 5980 | F11: =SUM(F6:F10) -> 13411.333 | G11: =IFERROR(F11/C11,0) -> 0.69161481
A14: Discount Walk-Down
A15: Gross list value (no discounts): | F15: =SUMPRODUCT(Calculator!B10:B14*Calculator!C10:C14*Calculator!B6) -> 22813.333
A16: Less: Bundle discount | E16: =Calculator!C19 -> 0.15 | F16: =-F15*Calculator!C19 -> -3422
A17: Less: Volume discount | E17: =Calculator!C21 -> 0 | F17: =-(F15+F16)*Calculator!C21 -> 0
A18: Net subscription revenue (monthly): | F18: =F15+F16+F17 -> 19391.333
A19: Effective discount vs list: | F19: =IFERROR((F15-F18)/F15,0) -> 0.15
A21: Margin Floor Check (minimum acceptable price per vehicle)
A22: Floor = Marginal × 2 (i.e. minimum 50% GM). If Effective Price falls below floor, you are eroding margin.
A23: Product | B23: Marginal (R) | C23: Floor @ 50% GM (R) | D23: Floor @ 60% GM (R) | E23: Current Effective Price (R) | F23: Status
A24: Tracking | B24: =Config!B5 -> 83 | C24: =B24*2 -> 166 | D24: =B24/0.4 -> 207.5 | E24: =Calculator!D10 -> 235.16667 | F24: =IF(E24<C24,"🚨 BELOW 50% FLOOR",IF(E24<D24,"⚠ Below 60%","✓ Healthy")) -> ✓ Healthy
A25: Fuel | B25: =Config!B6 -> 83 | C25: =B25*2 -> 166 | D25: =B25/0.4 -> 207.5 | E25: =Calculator!D11 -> 282.2 | F25: =IF(E25<C25,"🚨 BELOW 50% FLOOR",IF(E25<D25,"⚠ Below 60%","✓ Healthy")) -> ✓ Healthy
A26: Route Builder | B26: =Config!B7 -> 50 | C26: =B26*2 -> 100 | D26: =B26/0.4 -> 125 | E26: =Calculator!D12 -> 170 | F26: =IF(E26<C26,"🚨 BELOW 50% FLOOR",IF(E26<D26,"⚠ Below 60%","✓ Healthy")) -> ✓ Healthy
A27: Digital Journey | B27: =Config!B8 -> 83 | C27: =B27*2 -> 166 | D27: =B27/0.4 -> 207.5 | E27: =Calculator!D13 -> 282.2 | F27: =IF(E27<C27,"🚨 BELOW 50% FLOOR",IF(E27<D27,"⚠ Below 60%","✓ Healthy")) -> ✓ Healthy
A28: Stock Master | B28: =Config!B9 -> 250 | C28: =B28*2 -> 500 | D28: =B28/0.4 -> 625 | E28: =Calculator!D14 -> 850 | F28: =IF(E28<C28,"🚨 BELOW 50% FLOOR",IF(E28<D28,"⚠ Below 60%","✓ Healthy")) -> ✓ Healthy

Sheet Config
A1: Pricing Configuration
A3: Product Pricing
A4: Product | B4: Marginal Cost (R/license/mo) | C4: Target Gross Margin | D4: List Price (R/license/mo) | E4: Step Threshold (licenses) | F4: Step Cost (R/mo)
A5: Tracking | B5: 83 | C5: 0.7 | D5: =B5/(1-C5) -> 276.66667 | E5: 300 | F5: 25000
A6: Fuel | B6: 83 | C6: 0.75 | D6: =B6/(1-C6) -> 332 | E6: 300 | F6: 25000
A7: Route Builder | B7: 50 | C7: 0.75 | D7: =B7/(1-C7) -> 200 | E7: 500 | F7: 25000
A8: Digital Journey | B8: 83 | C8: 0.75 | D8: =B8/(1-C8) -> 332 | E8: 300 | F8: 25000
A9: Stock Master | B9: 250 | C9: 0.75 | D9: =B9/(1-C9) -> 1000 | E9: 100 | F9: 25000
A10: Fleetview | B10: 87 | C10: 0.75 | D10: =B10/(1-C10) -> 348 | E10: 100 | F10: 25000
A12: Bundle Discount Schedule
A13: # Products in Bundle | B13: Discount % | C13: Multiplier
A14: 1 | B14: 0 | C14: =1-B14 -> 1
A15: 2 | B15: 0.05 | C15: =1-B15 -> 0.95
A16: 3 | B16: 0.1 | C16: =1-B16 -> 0.9
A17: 4 | B17: 0.15 | C17: =1-B17 -> 0.85
A18: 5 | B18: 0.2 | C18: =1-B18 -> 0.8
A20: Volume Discount Schedule (Cliff Tiers)
A21: Min Vehicles | B21: Max Vehicles | C21: Tier Name | D21: Discount % | E21: Multiplier
A22: 1 | B22: 50 | C22: SMB | D22: 0 | E22: =1-D22 -> 1
A23: 51 | B23: 200 | C23: Mid-market | D23: 0.05 | E23: =1-D23 -> 0.95
A24: 201 | B24: 500 | C24: Upper mid | D24: 0.1 | E24: =1-D24 -> 0.9
A25: 501 | B25: 2000 | C25: Large | D25: 0.18 | E25: =1-D25 -> 0.82
A26: 2000 | B26: 999999 | C26: Enterprise | D26: 0.25 | E26: =1-D26 -> 0.75
A29: Implementation Hourly Rates
A30: Consultant rate (R / hour): | B30: 1000 | C30: standard delivery resource (junior)
A31: Senior Consultant rate (R / hour): | B31: 1325 | C31: architects, PMs, complex go-lives (senior)
A33: Hardware Cost Configuration
A34: SKU | B34: Cost (R) | C34: Markup % | D34: Sell Price (R) | E34: Notes
A35: Blackview Fort 1 | B35: 3938 | C35: 0.25 | D35: =B35*(1+C35) -> 4922.5 | E35: Handset option 1
A36: Blackview BV6200 | B36: 3999 | C36: 0.25 | D36: =B36*(1+C36) -> 4998.75 | E36: Handset option 2
A37: Oukitel G1S | B37: 2973 | C37: 0.25 | D37: =B37*(1+C37) -> 3716.25 | E37: Handset option 3
A38: Urovo Printer K419 (incl. case + car charger) | B38: 3606 | C38: 0.25 | D38: =B38*(1+C38) -> 4507.5 | E38: Mobile thermal printer (DJ)
A39: Teltonika FMB125 | B39: 639 | C39: 0.25 | D39: =B39*(1+C39) -> 798.75 | E39: Vehicle GPS — 1 per vehicle | H39: 1749
A40: Queclink GV620MG | B40: 1403 | C40: 0.25 | D40: =B40*(1+C40) -> 1753.75 | E40: Trailer GPS — 1 per trailer
A41: Omnicomm LS4 | B41: 1749 | C41: 0.25 | D41: =B41*(1+C41) -> 2186.25 | E41: Fuel probe — 1 per tank | G41: =106*16.5 -> 1749 | H41: =188*16.5 -> 3102
A42: Streamax 3 camera | B42: 8712 | C42: 0.25 | D42: =B42*(1+C42) -> 10890 | E42: Steamax 3 camera plus
A44: Installation Charges
A45: Scenario | B45: Rate (R)
A46: GPS Tracking Unit alone | B46: 800
A47: Fuel Probe alone (single probe, no GPS) | B47: 1200
...

Sheet Scenarios
A1: Scenario Comparison Tool
A2: Compare three deal configurations side-by-side. Use this to show clients the value of bundling/scaling.
B4: Scenario A | C4: Scenario B | D4: Scenario C
A5: Scenario name | B5: Tracking-only Entry | C5: Fuel + Route Builder + DJ | D5: Full Suite Enterprise (4-prod)
A6: Number of Vehicles | B6: 50 | C6: 250 | D6: 1200
A7: PRODUCTS INCLUDED
A8: Tracking | B8: TRUE | C8: 0 | D8: 0
A9: Fuel | B9: 0 | C9: TRUE | D9: TRUE
A10: Route Builder | B10: 0 | C10: TRUE | D10: TRUE
A11: Digital Journey | B11: 0 | C11: TRUE | D11: TRUE
A12: Stock Master | B12: 0 | C12: 0 | D12: TRUE
A14: CALCULATED OUTPUTS
A15: Products in bundle | B15: =SUMPRODUCT(--B8:B12) -> 1 | C15: =SUMPRODUCT(--C8:C12) -> 3 | D15: =SUMPRODUCT(--D8:D12) -> 4
A16: Bundle multiplier | B16: =IFERROR(VLOOKUP(B15,Config!$A$14:$C$18,3,FALSE),1) -> 1 | C16: =IFERROR(VLOOKUP(C15,Config!$A$14:$C$18,3,FALSE),1) -> 0.9 | D16: =IFERROR(VLOOKUP(D15,Config!$A$14:$C$18,3,FALSE),1) -> 0.85
A17: Volume multiplier | B17: =VLOOKUP(B6,Config!$A$22:$E$26,5,TRUE) -> 1 | C17: =VLOOKUP(C6,Config!$A$22:$E$26,5,TRUE) -> 0.9 | D17: =VLOOKUP(D6,Config!$A$22:$E$26,5,TRUE) -> 0.82
A18: Volume tier | B18: =VLOOKUP(B6,Config!$A$22:$E$26,3,TRUE) -> SMB | C18: =VLOOKUP(C6,Config!$A$22:$E$26,3,TRUE) -> Upper mid | D18: =VLOOKUP(D6,Config!$A$22:$E$26,3,TRUE) -> Large
A19: Effective discount on list | B19: =1-B16*B17 -> 0 | C19: =1-C16*C17 -> 0.19 | D19: =1-D16*D17 -> 0.303
A20: Monthly subscription revenue | B20: =SUMPRODUCT(B8:B12*Config!$D$5:$D$9*B6)*B16*B17 -> 13833.333 | C20: =SUMPRODUCT(C8:C12*Config!$D$5:$D$9*C6)*C16*C17 -> 174960 | D20: =SUMPRODUCT(D8:D12*Config!$D$5:$D$9*D6)*D16*D17 -> 1559049.6
A21: Annual subscription revenue | B21: =B20*12 -> 166000 | C21: =C20*12 -> 2099520 | D21: =D20*12 -> 18708595
A22: Monthly marginal cost | B22: =SUMPRODUCT(B8:B12*Config!$B$5:$B$9*B6) -> 4150 | C22: =SUMPRODUCT(C8:C12*Config!$B$5:$B$9*C6) -> 54000 | D22: =SUMPRODUCT(D8:D12*Config!$B$5:$B$9*D6) -> 559200
A23: Monthly contribution | B23: =B20-B22 -> 9683.3333 | C23: =C20-C22 -> 120960 | D23: =D20-D22 -> 999849.6
A24: Effective gross margin | B24: =IFERROR(B23/B20,0) -> 0.7 | C24: =IFERROR(C23/C20,0) -> 0.69135802 | D24: =IFERROR(D23/D20,0) -> 0.64131994
A25: Blended price per vehicle/mo | B25: =IFERROR(B20/B6,0) -> 276.66667 | C25: =IFERROR(C20/C6,0) -> 699.84 | D25: =IFERROR(D20/D6,0) -> 1299.208
A27: Tip: change YELLOW cells (scenario name, vehicles, product Yes/No) to compare different deal shapes.
